14:52:12,38 rospy.internal INFO topic[/step_done] adding connection to [http://simone-Aspire-V3-772G:45907/], count 0
14:52:12,39 rospy.internal INFO topic[/collision_count] adding connection to [http://simone-Aspire-V3-772G:45907/], count 0
14:52:12,80 rospy.internal INFO topic[/next_step] adding connection to [/server_endpoint], count 0
14:52:12,278 rospy.internal INFO topic[/rosout] adding connection to [/rosout], count 0
14:52:52,579 root INFO START TRIAL WITH HOLO
14:55:42,576 root INFO Human finished in: 134.94108247756958
14:55:44,35 root INFO Step 1: 136.39980030059814
14:56:09,487 root INFO Human finished in: 15.901960372924805
14:56:12,488 root INFO Step 2: 18.903220891952515
14:56:36,192 root INFO Human finished in: 14.020809173583984
14:56:40,296 root INFO Step 3: 18.12466335296631
14:57:00,511 root INFO Human finished in: 19.476395845413208
14:57:00,512 root INFO Step 4: 19.47696018218994
14:57:30,23 rospy.core INFO signal_shutdown [atexit]
14:57:30,31 rospy.internal INFO topic[/rosout] removing connection to /rosout
14:57:30,31 rospy.internal INFO topic[/next_step] removing connection to /server_endpoint
14:57:30,32 rospy.internal INFO topic[/step_done] removing connection to http://simone-Aspire-V3-772G:45907/
14:57:30,32 rospy.internal INFO topic[/collision_count] removing connection to http://simone-Aspire-V3-772G:45907/
14:57:30,32 rospy.impl.masterslave INFO atexit
14:57:30,33 rospy.internal ERROR Unable to initiate TCP/IP socket to simone-Aspire-V3-772G:38291 (http://simone-Aspire-V3-772G:45907/): Traceback (most recent call last):
  File "/opt/ros/noetic/lib/python3/dist-packages/rospy/impl/tcpros_base.py", line 562, in connect
    self.read_header()
  File "/opt/ros/noetic/lib/python3/dist-packages/rospy/impl/tcpros_base.py", line 657, in read_header
    self._validate_header(read_ros_handshake_header(sock, self.read_buff, self.protocol.buff_size))
  File "/opt/ros/noetic/lib/python3/dist-packages/rospy/impl/tcpros_base.py", line 600, in _validate_header
    raise TransportInitError("remote error reported: %s"%header['error'])
rospy.exceptions.TransportInitError: remote error reported: node shutting down

15:02:10,968 rospy.internal INFO topic[/rosout] adding connection to [/rosout], count 0
15:02:11,46 rospy.internal INFO topic[/next_step] adding connection to [/server_endpoint], count 0
15:02:11,78 rospy.internal INFO topic[/step_done] adding connection to [http://simone-Aspire-V3-772G:37363/], count 0
15:02:11,79 rospy.internal INFO topic[/collision_count] adding connection to [http://simone-Aspire-V3-772G:37363/], count 0
15:02:51,22 rospy.core INFO signal_shutdown [atexit]
15:02:51,27 rospy.internal INFO topic[/rosout] removing connection to /rosout
15:02:51,28 rospy.internal INFO topic[/next_step] removing connection to /server_endpoint
15:02:51,28 rospy.internal INFO topic[/step_done] removing connection to http://simone-Aspire-V3-772G:37363/
15:02:51,28 rospy.internal INFO topic[/collision_count] removing connection to http://simone-Aspire-V3-772G:37363/
15:02:51,29 rospy.impl.masterslave INFO atexit
15:03:21,632 rospy.internal INFO topic[/step_done] adding connection to [http://simone-Aspire-V3-772G:41599/], count 0
15:03:21,633 rospy.internal INFO topic[/collision_count] adding connection to [http://simone-Aspire-V3-772G:41599/], count 0
15:03:21,710 rospy.internal INFO topic[/next_step] adding connection to [/server_endpoint], count 0
15:03:21,811 rospy.internal INFO topic[/rosout] adding connection to [/rosout], count 0
15:04:10,807 root INFO START TRIAL WITH HOLO
15:04:41,704 root INFO Human finished in: 24.89345669746399
15:04:41,705 root INFO Step 1: 24.89396333694458
15:05:01,693 root INFO Human finished in: 17.400809049606323
15:05:05,503 root INFO Step 2: 21.21097493171692
15:05:24,943 root INFO Human finished in: 14.143801212310791
15:05:31,702 root INFO Step 3: 20.903170824050903
15:05:53,324 root INFO Human finished in: 16.489677667617798
15:05:58,369 root INFO Step 4: 21.53470468521118
15:08:03,612 rospy.core INFO signal_shutdown [atexit]
15:08:03,620 rospy.internal WARNING Unknown error initiating TCP/IP socket to simone-Aspire-V3-772G:46119 (http://simone-Aspire-V3-772G:41599/): Traceback (most recent call last):
  File "/opt/ros/noetic/lib/python3/dist-packages/rospy/impl/tcpros_base.py", line 560, in connect
    self.socket.connect((dest_addr, dest_port))
ConnectionRefusedError: [Errno 111] Connection refused

15:08:03,620 rospy.internal INFO topic[/collision_count] removing connection to http://simone-Aspire-V3-772G:41599/
15:08:03,620 rospy.internal WARNING Unknown error initiating TCP/IP socket to simone-Aspire-V3-772G:46119 (http://simone-Aspire-V3-772G:41599/): Traceback (most recent call last):
  File "/opt/ros/noetic/lib/python3/dist-packages/rospy/impl/tcpros_base.py", line 562, in connect
    self.read_header()
  File "/opt/ros/noetic/lib/python3/dist-packages/rospy/impl/tcpros_base.py", line 657, in read_header
    self._validate_header(read_ros_handshake_header(sock, self.read_buff, self.protocol.buff_size))
  File "/opt/ros/noetic/lib/python3/dist-packages/rosgraph/network.py", line 357, in read_ros_handshake_header
    d = sock.recv(buff_size)
ConnectionResetError: [Errno 104] Connection reset by peer

15:08:03,620 rospy.internal INFO topic[/step_done] removing connection to http://simone-Aspire-V3-772G:41599/
15:08:03,620 rospy.internal INFO topic[/rosout] removing connection to /rosout
15:08:03,621 rospy.internal INFO topic[/next_step] removing connection to /server_endpoint
15:08:03,621 rospy.impl.masterslave INFO atexit
15:10:50,877 rospy.internal INFO topic[/step_done] adding connection to [http://simone-Aspire-V3-772G:36573/], count 0
15:10:50,879 rospy.internal INFO topic[/collision_count] adding connection to [http://simone-Aspire-V3-772G:36573/], count 0
15:10:50,963 rospy.internal INFO topic[/next_step] adding connection to [/server_endpoint], count 0
15:10:51,59 rospy.internal INFO topic[/rosout] adding connection to [/rosout], count 0
15:11:21,399 root INFO START TRIAL WITH HOLO
15:16:36,927 rospy.core INFO signal_shutdown [atexit]
15:16:36,936 rospy.internal INFO topic[/rosout] removing connection to /rosout
15:16:36,942 rospy.internal INFO topic[/next_step] removing connection to /server_endpoint
15:16:36,943 rospy.internal WARNING Unknown error initiating TCP/IP socket to simone-Aspire-V3-772G:34853 (http://simone-Aspire-V3-772G:36573/): Traceback (most recent call last):
  File "/opt/ros/noetic/lib/python3/dist-packages/rospy/impl/tcpros_base.py", line 562, in connect
    self.read_header()
  File "/opt/ros/noetic/lib/python3/dist-packages/rospy/impl/tcpros_base.py", line 657, in read_header
    self._validate_header(read_ros_handshake_header(sock, self.read_buff, self.protocol.buff_size))
  File "/opt/ros/noetic/lib/python3/dist-packages/rosgraph/network.py", line 357, in read_ros_handshake_header
    d = sock.recv(buff_size)
ConnectionResetError: [Errno 104] Connection reset by peer

15:16:36,943 rospy.internal INFO topic[/step_done] removing connection to http://simone-Aspire-V3-772G:36573/
15:16:36,943 rospy.internal WARNING Unknown error initiating TCP/IP socket to simone-Aspire-V3-772G:34853 (http://simone-Aspire-V3-772G:36573/): Traceback (most recent call last):
  File "/opt/ros/noetic/lib/python3/dist-packages/rospy/impl/tcpros_base.py", line 562, in connect
    self.read_header()
  File "/opt/ros/noetic/lib/python3/dist-packages/rospy/impl/tcpros_base.py", line 657, in read_header
    self._validate_header(read_ros_handshake_header(sock, self.read_buff, self.protocol.buff_size))
  File "/opt/ros/noetic/lib/python3/dist-packages/rosgraph/network.py", line 357, in read_ros_handshake_header
    d = sock.recv(buff_size)
ConnectionResetError: [Errno 104] Connection reset by peer

15:16:36,943 rospy.internal INFO topic[/collision_count] removing connection to http://simone-Aspire-V3-772G:36573/
15:16:36,944 rospy.internal INFO topic[/step_done] removing connection to http://simone-Aspire-V3-772G:36573/
15:16:36,944 rospy.topics ERROR Traceback (most recent call last):
  File "/opt/ros/noetic/lib/python3/dist-packages/rospy/topics.py", line 326, in close
    c.close()
  File "/opt/ros/noetic/lib/python3/dist-packages/rospy/impl/tcpros_base.py", line 846, in close
    self.socket.close()
AttributeError: 'NoneType' object has no attribute 'close'

15:16:36,944 rospy.impl.masterslave INFO atexit
15:20:24,931 rospy.internal INFO topic[/next_step] adding connection to [/server_endpoint], count 0
15:20:25,16 rospy.internal INFO topic[/step_done] adding connection to [http://simone-Aspire-V3-772G:41997/], count 0
15:20:25,23 rospy.internal INFO topic[/collision_count] adding connection to [http://simone-Aspire-V3-772G:41997/], count 0
15:20:25,117 rospy.internal INFO topic[/rosout] adding connection to [/rosout], count 0
15:21:01,54 root INFO START TRIAL WITH HOLO
15:22:49,250 rospy.core INFO signal_shutdown [atexit]
15:22:49,256 rospy.internal INFO topic[/rosout] removing connection to /rosout
15:22:49,257 rospy.internal INFO topic[/next_step] removing connection to /server_endpoint
15:22:49,263 rospy.internal INFO topic[/step_done] removing connection to http://simone-Aspire-V3-772G:41997/
15:22:49,264 rospy.internal ERROR Unable to initiate TCP/IP socket to simone-Aspire-V3-772G:33881 (http://simone-Aspire-V3-772G:41997/): Traceback (most recent call last):
  File "/opt/ros/noetic/lib/python3/dist-packages/rospy/impl/tcpros_base.py", line 562, in connect
    self.read_header()
  File "/opt/ros/noetic/lib/python3/dist-packages/rospy/impl/tcpros_base.py", line 657, in read_header
    self._validate_header(read_ros_handshake_header(sock, self.read_buff, self.protocol.buff_size))
  File "/opt/ros/noetic/lib/python3/dist-packages/rospy/impl/tcpros_base.py", line 600, in _validate_header
    raise TransportInitError("remote error reported: %s"%header['error'])
rospy.exceptions.TransportInitError: remote error reported: node shutting down

15:22:49,264 rospy.internal INFO topic[/collision_count] removing connection to http://simone-Aspire-V3-772G:41997/
15:22:49,264 rospy.impl.masterslave INFO atexit
15:22:49,265 rospy.internal WARNING Unknown error initiating TCP/IP socket to simone-Aspire-V3-772G:33881 (http://simone-Aspire-V3-772G:41997/): Traceback (most recent call last):
  File "/opt/ros/noetic/lib/python3/dist-packages/rospy/impl/tcpros_base.py", line 560, in connect
    self.socket.connect((dest_addr, dest_port))
OSError: [Errno 9] Bad file descriptor

15:28:52,494 rospy.internal INFO topic[/next_step] adding connection to [/server_endpoint], count 0
15:28:52,508 rospy.internal INFO topic[/step_done] adding connection to [http://simone-Aspire-V3-772G:35135/], count 0
15:28:52,513 rospy.internal INFO topic[/collision_count] adding connection to [http://simone-Aspire-V3-772G:35135/], count 0
15:28:52,611 rospy.internal INFO topic[/rosout] adding connection to [/rosout], count 0
15:29:22,676 root INFO START TRIAL WITH HOLO
15:34:38,780 rospy.core INFO signal_shutdown [atexit]
15:34:38,789 rospy.internal INFO topic[/rosout] removing connection to /rosout
15:34:38,793 rospy.internal INFO topic[/next_step] removing connection to /server_endpoint
15:34:38,793 rospy.internal INFO topic[/step_done] removing connection to http://simone-Aspire-V3-772G:35135/
15:34:38,795 rospy.internal INFO topic[/collision_count] removing connection to http://simone-Aspire-V3-772G:35135/
15:34:38,795 rospy.impl.masterslave INFO atexit
15:34:38,795 rospy.internal WARNING Unknown error initiating TCP/IP socket to simone-Aspire-V3-772G:39285 (http://simone-Aspire-V3-772G:35135/): Traceback (most recent call last):
  File "/opt/ros/noetic/lib/python3/dist-packages/rospy/impl/tcpros_base.py", line 562, in connect
    self.read_header()
  File "/opt/ros/noetic/lib/python3/dist-packages/rospy/impl/tcpros_base.py", line 657, in read_header
    self._validate_header(read_ros_handshake_header(sock, self.read_buff, self.protocol.buff_size))
  File "/opt/ros/noetic/lib/python3/dist-packages/rosgraph/network.py", line 357, in read_ros_handshake_header
    d = sock.recv(buff_size)
ConnectionResetError: [Errno 104] Connection reset by peer

15:34:38,794 rospy.internal ERROR Unable to initiate TCP/IP socket to simone-Aspire-V3-772G:39285 (http://simone-Aspire-V3-772G:35135/): Traceback (most recent call last):
  File "/opt/ros/noetic/lib/python3/dist-packages/rospy/impl/tcpros_base.py", line 562, in connect
    self.read_header()
  File "/opt/ros/noetic/lib/python3/dist-packages/rospy/impl/tcpros_base.py", line 657, in read_header
    self._validate_header(read_ros_handshake_header(sock, self.read_buff, self.protocol.buff_size))
  File "/opt/ros/noetic/lib/python3/dist-packages/rospy/impl/tcpros_base.py", line 600, in _validate_header
    raise TransportInitError("remote error reported: %s"%header['error'])
rospy.exceptions.TransportInitError: remote error reported: node shutting down

