15:37:06,426 rospy.internal INFO topic[/step_done] adding connection to [http://simone-Aspire-V3-772G:43197/], count 0
15:37:06,426 rospy.internal INFO topic[/collision_count] adding connection to [http://simone-Aspire-V3-772G:43197/], count 0
15:37:06,468 rospy.internal INFO topic[/next_step] adding connection to [/server_endpoint], count 0
15:37:06,569 rospy.internal INFO topic[/rosout] adding connection to [/rosout], count 0
15:37:54,527 root INFO Human finished in: 26.107681274414062
15:37:54,528 root INFO Step 1: 26.109308004379272
15:38:12,661 root INFO Human finished in: 16.102349996566772
15:38:15,884 root INFO Step 2: 19.324748039245605
15:38:40,277 root INFO Human finished in: 23.34307074546814
15:38:40,319 root INFO Step 3: 23.38468098640442
15:39:06,171 root INFO Human finished in: 23.458877086639404
15:39:06,172 root INFO Step 4: 23.459404706954956
15:40:57,191 rospy.core INFO signal_shutdown [atexit]
15:40:57,200 rospy.internal INFO topic[/rosout] removing connection to /rosout
15:40:57,202 rospy.internal INFO topic[/next_step] removing connection to /server_endpoint
15:40:57,203 rospy.internal INFO topic[/step_done] removing connection to http://simone-Aspire-V3-772G:43197/
15:40:57,203 rospy.internal INFO topic[/collision_count] removing connection to http://simone-Aspire-V3-772G:43197/
15:40:57,204 rospy.internal ERROR Unable to initiate TCP/IP socket to simone-Aspire-V3-772G:35807 (http://simone-Aspire-V3-772G:43197/): Traceback (most recent call last):
  File "/opt/ros/noetic/lib/python3/dist-packages/rospy/impl/tcpros_base.py", line 562, in connect
    self.read_header()
  File "/opt/ros/noetic/lib/python3/dist-packages/rospy/impl/tcpros_base.py", line 657, in read_header
    self._validate_header(read_ros_handshake_header(sock, self.read_buff, self.protocol.buff_size))
  File "/opt/ros/noetic/lib/python3/dist-packages/rospy/impl/tcpros_base.py", line 600, in _validate_header
    raise TransportInitError("remote error reported: %s"%header['error'])
rospy.exceptions.TransportInitError: remote error reported: node shutting down

15:40:57,204 rospy.impl.masterslave INFO atexit
15:46:42,182 rospy.internal INFO topic[/next_step] adding connection to [/server_endpoint], count 0
15:46:42,216 rospy.internal INFO topic[/step_done] adding connection to [http://simone-Aspire-V3-772G:33737/], count 0
15:46:42,223 rospy.internal INFO topic[/collision_count] adding connection to [http://simone-Aspire-V3-772G:33737/], count 0
15:46:42,326 rospy.internal INFO topic[/rosout] adding connection to [/rosout], count 0
15:48:27,369 rospy.core INFO signal_shutdown [atexit]
15:48:27,382 rospy.internal ERROR Unable to initiate TCP/IP socket to simone-Aspire-V3-772G:34075 (http://simone-Aspire-V3-772G:33737/): Traceback (most recent call last):
  File "/opt/ros/noetic/lib/python3/dist-packages/rospy/impl/tcpros_base.py", line 562, in connect
    self.read_header()
  File "/opt/ros/noetic/lib/python3/dist-packages/rospy/impl/tcpros_base.py", line 657, in read_header
    self._validate_header(read_ros_handshake_header(sock, self.read_buff, self.protocol.buff_size))
  File "/opt/ros/noetic/lib/python3/dist-packages/rospy/impl/tcpros_base.py", line 600, in _validate_header
    raise TransportInitError("remote error reported: %s"%header['error'])
rospy.exceptions.TransportInitError: remote error reported: node shutting down

15:48:27,384 rospy.internal WARNING Unknown error initiating TCP/IP socket to simone-Aspire-V3-772G:34075 (http://simone-Aspire-V3-772G:33737/): Traceback (most recent call last):
  File "/opt/ros/noetic/lib/python3/dist-packages/rospy/impl/tcpros_base.py", line 562, in connect
    self.read_header()
  File "/opt/ros/noetic/lib/python3/dist-packages/rospy/impl/tcpros_base.py", line 657, in read_header
    self._validate_header(read_ros_handshake_header(sock, self.read_buff, self.protocol.buff_size))
  File "/opt/ros/noetic/lib/python3/dist-packages/rosgraph/network.py", line 357, in read_ros_handshake_header
    d = sock.recv(buff_size)
ConnectionResetError: [Errno 104] Connection reset by peer

15:48:27,385 rospy.internal INFO topic[/rosout] removing connection to /rosout
15:48:27,385 rospy.internal INFO topic[/collision_count] removing connection to http://simone-Aspire-V3-772G:33737/
15:48:27,385 rospy.internal INFO topic[/next_step] removing connection to /server_endpoint
15:48:27,385 rospy.internal INFO topic[/step_done] removing connection to http://simone-Aspire-V3-772G:33737/
15:48:27,385 rospy.impl.masterslave INFO atexit
16:02:07,462 rospy.internal INFO topic[/step_done] adding connection to [http://simone-Aspire-V3-772G:37759/], count 0
16:02:07,465 rospy.internal INFO topic[/collision_count] adding connection to [http://simone-Aspire-V3-772G:37759/], count 0
16:02:07,540 rospy.internal INFO topic[/next_step] adding connection to [/server_endpoint], count 0
16:02:07,645 rospy.internal INFO topic[/rosout] adding connection to [/rosout], count 0
16:03:41,550 root INFO Step 1: 64.26526689529419
16:03:41,551 root INFO Human finished in: 64.26611471176147
16:04:06,237 root INFO Human finished in: 21.129322052001953
16:04:06,241 root INFO Step 2: 21.133418560028076
16:04:32,194 root INFO Human finished in: 21.653982400894165
16:04:32,194 root INFO Step 3: 21.654646158218384
16:20:57,239 rospy.core INFO signal_shutdown [atexit]
16:20:57,247 rospy.internal INFO topic[/rosout] removing connection to /rosout
16:20:57,247 rospy.internal INFO topic[/next_step] removing connection to /server_endpoint
16:20:57,248 rospy.internal INFO topic[/step_done] removing connection to http://simone-Aspire-V3-772G:37759/
16:20:57,249 rospy.internal ERROR Unable to initiate TCP/IP socket to simone-Aspire-V3-772G:34711 (http://simone-Aspire-V3-772G:37759/): Traceback (most recent call last):
  File "/opt/ros/noetic/lib/python3/dist-packages/rospy/impl/tcpros_base.py", line 562, in connect
    self.read_header()
  File "/opt/ros/noetic/lib/python3/dist-packages/rospy/impl/tcpros_base.py", line 657, in read_header
    self._validate_header(read_ros_handshake_header(sock, self.read_buff, self.protocol.buff_size))
  File "/opt/ros/noetic/lib/python3/dist-packages/rospy/impl/tcpros_base.py", line 600, in _validate_header
    raise TransportInitError("remote error reported: %s"%header['error'])
rospy.exceptions.TransportInitError: remote error reported: node shutting down

16:20:57,249 rospy.internal INFO topic[/collision_count] removing connection to http://simone-Aspire-V3-772G:37759/
16:20:57,250 rospy.impl.masterslave INFO atexit
16:20:57,251 rospy.internal ERROR Unable to initiate TCP/IP socket to simone-Aspire-V3-772G:34711 (http://simone-Aspire-V3-772G:37759/): Traceback (most recent call last):
  File "/opt/ros/noetic/lib/python3/dist-packages/rospy/impl/tcpros_base.py", line 562, in connect
    self.read_header()
  File "/opt/ros/noetic/lib/python3/dist-packages/rospy/impl/tcpros_base.py", line 657, in read_header
    self._validate_header(read_ros_handshake_header(sock, self.read_buff, self.protocol.buff_size))
  File "/opt/ros/noetic/lib/python3/dist-packages/rospy/impl/tcpros_base.py", line 600, in _validate_header
    raise TransportInitError("remote error reported: %s"%header['error'])
rospy.exceptions.TransportInitError: remote error reported: node shutting down

16:46:15,386 rospy.internal INFO topic[/next_step] adding connection to [/server_endpoint], count 0
16:46:15,409 rospy.internal INFO topic[/rosout] adding connection to [/rosout], count 0
16:46:15,416 rospy.internal INFO topic[/step_done] adding connection to [http://simone-Aspire-V3-772G:46141/], count 0
16:46:15,419 rospy.internal INFO topic[/collision_count] adding connection to [http://simone-Aspire-V3-772G:46141/], count 0
16:47:33,333 root INFO Human finished in: 35.418214082717896
16:47:33,334 root INFO Step 1: 35.419339656829834
16:48:32,583 root INFO Step 2: 56.16648054122925
16:48:32,583 root INFO Human finished in: 56.16680431365967
16:48:55,797 root INFO Human finished in: 20.470638513565063
16:48:55,798 root INFO Step 3: 20.471635580062866
16:49:29,426 root INFO Human finished in: 28.196167469024658
16:49:29,427 root INFO Step 4: 28.196550607681274
16:49:55,332 root INFO Reset count: 1
16:49:55,332 root INFO END TRIAL
16:49:55,431 root INFO Collisions: 2
16:49:56,608 root INFO START TRIAL WITH HOLO
16:50:36,235 root INFO Human finished in: 32.4402232170105
16:50:36,270 root INFO Step 1: 32.47587776184082
16:50:54,8 root INFO Human finished in: 15.405460119247437
16:51:25,89 root INFO Human finished in: 46.48719096183777
16:51:25,93 root INFO Step 2: 46.49026894569397
16:51:41,659 root INFO Human finished in: 13.964530944824219
16:51:46,769 root INFO Step 3: 19.07430601119995
16:52:08,987 root INFO Human finished in: 17.160470485687256
16:52:10,920 root INFO Step 4: 19.09386444091797
16:52:19,546 root INFO Reset count: 0
16:52:19,546 root INFO END TRIAL
16:52:19,659 root INFO Collisions: 2
16:53:19,827 rospy.core INFO signal_shutdown [atexit]
16:53:19,837 rospy.internal ERROR Unable to initiate TCP/IP socket to simone-Aspire-V3-772G:44153 (http://simone-Aspire-V3-772G:46141/): Traceback (most recent call last):
  File "/opt/ros/noetic/lib/python3/dist-packages/rospy/impl/tcpros_base.py", line 562, in connect
    self.read_header()
  File "/opt/ros/noetic/lib/python3/dist-packages/rospy/impl/tcpros_base.py", line 657, in read_header
    self._validate_header(read_ros_handshake_header(sock, self.read_buff, self.protocol.buff_size))
  File "/opt/ros/noetic/lib/python3/dist-packages/rospy/impl/tcpros_base.py", line 600, in _validate_header
    raise TransportInitError("remote error reported: %s"%header['error'])
rospy.exceptions.TransportInitError: remote error reported: node shutting down

16:53:19,840 rospy.internal INFO topic[/rosout] removing connection to /rosout
16:53:19,840 rospy.internal INFO topic[/next_step] removing connection to /server_endpoint
16:53:19,840 rospy.internal INFO topic[/step_done] removing connection to http://simone-Aspire-V3-772G:46141/
16:53:19,840 rospy.internal INFO topic[/collision_count] removing connection to http://simone-Aspire-V3-772G:46141/
16:53:19,841 rospy.impl.masterslave INFO atexit
16:59:42,620 rospy.internal INFO topic[/step_done] adding connection to [http://simone-Aspire-V3-772G:41195/], count 0
16:59:42,623 rospy.internal INFO topic[/collision_count] adding connection to [http://simone-Aspire-V3-772G:41195/], count 0
16:59:42,686 rospy.internal INFO topic[/next_step] adding connection to [/server_endpoint], count 0
16:59:42,791 rospy.internal INFO topic[/rosout] adding connection to [/rosout], count 0
17:01:36,198 root INFO Human finished in: 68.70601511001587
17:01:36,199 root INFO Step 1: 68.70692443847656
17:02:07,626 root INFO Human finished in: 29.345751523971558
17:02:07,660 root INFO Step 2: 29.379115343093872
17:02:28,292 root INFO Human finished in: 17.491913318634033
17:02:29,261 root INFO Step 3: 18.46117115020752
17:03:27,124 root INFO Reset count: 0
17:03:27,124 root INFO END TRIAL
17:03:27,224 root INFO Collisions: 3
17:05:48,638 root INFO Reset count: 0
17:05:48,638 root INFO END TRIAL
17:05:48,755 root INFO Collisions: 8
17:06:41,959 root INFO Human finished in: 48.49512219429016
17:06:41,961 root INFO Step 1: 48.49698328971863
17:07:48,721 root INFO Human finished in: 56.69024920463562
17:07:48,721 root INFO Step 2: 56.690727949142456
17:09:19,229 rospy.core INFO signal_shutdown [atexit]
17:09:19,238 rospy.internal ERROR Unable to initiate TCP/IP socket to simone-Aspire-V3-772G:44131 (http://simone-Aspire-V3-772G:41195/): Traceback (most recent call last):
  File "/opt/ros/noetic/lib/python3/dist-packages/rospy/impl/tcpros_base.py", line 562, in connect
    self.read_header()
  File "/opt/ros/noetic/lib/python3/dist-packages/rospy/impl/tcpros_base.py", line 657, in read_header
    self._validate_header(read_ros_handshake_header(sock, self.read_buff, self.protocol.buff_size))
  File "/opt/ros/noetic/lib/python3/dist-packages/rospy/impl/tcpros_base.py", line 600, in _validate_header
    raise TransportInitError("remote error reported: %s"%header['error'])
rospy.exceptions.TransportInitError: remote error reported: node shutting down

17:09:19,240 rospy.internal INFO topic[/rosout] removing connection to /rosout
17:09:19,241 rospy.internal INFO topic[/next_step] removing connection to /server_endpoint
17:09:19,240 rospy.internal ERROR Unable to initiate TCP/IP socket to simone-Aspire-V3-772G:44131 (http://simone-Aspire-V3-772G:41195/): Traceback (most recent call last):
  File "/opt/ros/noetic/lib/python3/dist-packages/rospy/impl/tcpros_base.py", line 562, in connect
    self.read_header()
  File "/opt/ros/noetic/lib/python3/dist-packages/rospy/impl/tcpros_base.py", line 657, in read_header
    self._validate_header(read_ros_handshake_header(sock, self.read_buff, self.protocol.buff_size))
  File "/opt/ros/noetic/lib/python3/dist-packages/rospy/impl/tcpros_base.py", line 600, in _validate_header
    raise TransportInitError("remote error reported: %s"%header['error'])
rospy.exceptions.TransportInitError: remote error reported: node shutting down

17:09:19,241 rospy.internal INFO topic[/step_done] removing connection to http://simone-Aspire-V3-772G:41195/
17:09:19,241 rospy.internal INFO topic[/collision_count] removing connection to http://simone-Aspire-V3-772G:41195/
17:09:19,241 rospy.impl.masterslave INFO atexit
17:10:48,671 rospy.internal INFO topic[/step_done] adding connection to [http://simone-Aspire-V3-772G:36327/], count 0
17:10:48,673 rospy.internal INFO topic[/collision_count] adding connection to [http://simone-Aspire-V3-772G:36327/], count 0
17:10:48,695 rospy.internal INFO topic[/next_step] adding connection to [/server_endpoint], count 0
17:10:48,897 rospy.internal INFO topic[/rosout] adding connection to [/rosout], count 0
17:17:27,797 rospy.core INFO signal_shutdown [atexit]
17:17:27,806 rospy.internal INFO topic[/rosout] removing connection to /rosout
17:17:27,808 rospy.internal INFO topic[/next_step] removing connection to /server_endpoint
17:17:27,808 rospy.internal INFO topic[/step_done] removing connection to http://simone-Aspire-V3-772G:36327/
17:17:27,808 rospy.internal INFO topic[/collision_count] removing connection to http://simone-Aspire-V3-772G:36327/
17:17:27,808 rospy.impl.masterslave INFO atexit
17:35:57,382 rospy.internal INFO topic[/rosout] adding connection to [/rosout], count 0
17:35:57,395 rospy.internal INFO topic[/next_step] adding connection to [/server_endpoint], count 0
17:35:57,416 rospy.internal INFO topic[/step_done] adding connection to [http://simone-Aspire-V3-772G:39097/], count 0
17:35:57,418 rospy.internal INFO topic[/collision_count] adding connection to [http://simone-Aspire-V3-772G:39097/], count 0
17:44:43,300 rospy.core INFO signal_shutdown [atexit]
17:44:43,311 rospy.internal INFO topic[/rosout] removing connection to /rosout
17:44:43,311 rospy.internal INFO topic[/next_step] removing connection to /server_endpoint
17:44:43,311 rospy.internal INFO topic[/step_done] removing connection to http://simone-Aspire-V3-772G:39097/
17:44:43,311 rospy.internal INFO topic[/collision_count] removing connection to http://simone-Aspire-V3-772G:39097/
17:44:43,311 rospy.impl.masterslave INFO atexit
17:44:43,314 rospy.internal WARNING Unknown error initiating TCP/IP socket to simone-Aspire-V3-772G:36575 (http://simone-Aspire-V3-772G:39097/): Traceback (most recent call last):
  File "/opt/ros/noetic/lib/python3/dist-packages/rospy/impl/tcpros_base.py", line 562, in connect
    self.read_header()
  File "/opt/ros/noetic/lib/python3/dist-packages/rospy/impl/tcpros_base.py", line 657, in read_header
    self._validate_header(read_ros_handshake_header(sock, self.read_buff, self.protocol.buff_size))
  File "/opt/ros/noetic/lib/python3/dist-packages/rosgraph/network.py", line 357, in read_ros_handshake_header
    d = sock.recv(buff_size)
ConnectionResetError: [Errno 104] Connection reset by peer

17:44:43,315 rospy.internal WARNING Unknown error initiating TCP/IP socket to simone-Aspire-V3-772G:36575 (http://simone-Aspire-V3-772G:39097/): Traceback (most recent call last):
  File "/opt/ros/noetic/lib/python3/dist-packages/rospy/impl/tcpros_base.py", line 562, in connect
    self.read_header()
  File "/opt/ros/noetic/lib/python3/dist-packages/rospy/impl/tcpros_base.py", line 657, in read_header
    self._validate_header(read_ros_handshake_header(sock, self.read_buff, self.protocol.buff_size))
  File "/opt/ros/noetic/lib/python3/dist-packages/rosgraph/network.py", line 357, in read_ros_handshake_header
    d = sock.recv(buff_size)
ConnectionResetError: [Errno 104] Connection reset by peer

17:45:09,955 rospy.internal INFO topic[/next_step] adding connection to [/server_endpoint], count 0
17:45:09,983 rospy.internal INFO topic[/step_done] adding connection to [http://simone-Aspire-V3-772G:33209/], count 0
17:45:09,984 rospy.internal INFO topic[/collision_count] adding connection to [http://simone-Aspire-V3-772G:33209/], count 0
17:45:10,82 rospy.internal INFO topic[/rosout] adding connection to [/rosout], count 0
17:57:17,210 root INFO Reset count: 0
17:57:17,211 root INFO END TRIAL
18:05:33,483 rospy.core INFO signal_shutdown [atexit]
18:05:33,491 rospy.internal INFO topic[/rosout] removing connection to /rosout
18:05:33,492 rospy.internal INFO topic[/next_step] removing connection to /server_endpoint
18:05:33,495 rospy.internal WARNING Unknown error initiating TCP/IP socket to simone-Aspire-V3-772G:34179 (http://simone-Aspire-V3-772G:33209/): Traceback (most recent call last):
  File "/opt/ros/noetic/lib/python3/dist-packages/rospy/impl/tcpros_base.py", line 560, in connect
    self.socket.connect((dest_addr, dest_port))
ConnectionRefusedError: [Errno 111] Connection refused

18:05:33,496 rospy.internal INFO topic[/step_done] removing connection to http://simone-Aspire-V3-772G:33209/
18:05:33,496 rospy.internal WARNING Unknown error initiating TCP/IP socket to simone-Aspire-V3-772G:34179 (http://simone-Aspire-V3-772G:33209/): Traceback (most recent call last):
  File "/opt/ros/noetic/lib/python3/dist-packages/rospy/impl/tcpros_base.py", line 562, in connect
    self.read_header()
  File "/opt/ros/noetic/lib/python3/dist-packages/rospy/impl/tcpros_base.py", line 657, in read_header
    self._validate_header(read_ros_handshake_header(sock, self.read_buff, self.protocol.buff_size))
  File "/opt/ros/noetic/lib/python3/dist-packages/rosgraph/network.py", line 357, in read_ros_handshake_header
    d = sock.recv(buff_size)
ConnectionResetError: [Errno 104] Connection reset by peer

18:05:33,497 rospy.internal INFO topic[/collision_count] removing connection to http://simone-Aspire-V3-772G:33209/
18:05:33,497 rospy.internal INFO topic[/step_done] removing connection to http://simone-Aspire-V3-772G:33209/
18:05:33,497 rospy.topics ERROR Traceback (most recent call last):
  File "/opt/ros/noetic/lib/python3/dist-packages/rospy/topics.py", line 326, in close
    c.close()
  File "/opt/ros/noetic/lib/python3/dist-packages/rospy/impl/tcpros_base.py", line 846, in close
    self.socket.close()
AttributeError: 'NoneType' object has no attribute 'close'

18:05:33,497 rospy.impl.masterslave INFO atexit
